{"trial_id": "01", "hyperparameters": {"space": [{"class_name": "Int", "config": {"name": "filters", "default": null, "conditions": [], "min_value": 16, "max_value": 64, "step": 16, "sampling": "linear"}}, {"class_name": "Int", "config": {"name": "units", "default": null, "conditions": [], "min_value": 32, "max_value": 128, "step": 32, "sampling": "linear"}}, {"class_name": "Float", "config": {"name": "dropout", "default": 0.2, "conditions": [], "min_value": 0.2, "max_value": 0.5, "step": 0.1, "sampling": "linear"}}, {"class_name": "Choice", "config": {"name": "learning_rate", "default": 0.0001, "conditions": [], "values": [0.0001, 0.001, 0.01], "ordered": true}}], "values": {"filters": 48, "units": 64, "dropout": 0.30000000000000004, "learning_rate": 0.01}}, "metrics": {"metrics": {}}, "score": null, "best_step": 0, "status": "FAILED", "message": "Traceback (most recent call last):\n  File \"C:\\Users\\HP\\AppData\\Local\\Programs\\Python\\Python311\\Lib\\site-packages\\keras_tuner\\src\\engine\\base_tuner.py\", line 274, in _try_run_and_update_trial\n    self._run_and_update_trial(trial, *fit_args, **fit_kwargs)\n  File \"C:\\Users\\HP\\AppData\\Local\\Programs\\Python\\Python311\\Lib\\site-packages\\keras_tuner\\src\\engine\\base_tuner.py\", line 239, in _run_and_update_trial\n    results = self.run_trial(trial, *fit_args, **fit_kwargs)\n              ^^^^^^^^^^^^^^^^^^^^^^^^^^^^^^^^^^^^^^^^^^^^^^\n  File \"C:\\Users\\HP\\AppData\\Local\\Programs\\Python\\Python311\\Lib\\site-packages\\keras_tuner\\src\\engine\\tuner.py\", line 314, in run_trial\n    obj_value = self._build_and_fit_model(trial, *args, **copied_kwargs)\n                ^^^^^^^^^^^^^^^^^^^^^^^^^^^^^^^^^^^^^^^^^^^^^^^^^^^^^^^^\n  File \"C:\\Users\\HP\\AppData\\Local\\Programs\\Python\\Python311\\Lib\\site-packages\\keras_tuner\\src\\engine\\tuner.py\", line 233, in _build_and_fit_model\n    results = self.hypermodel.fit(hp, model, *args, **kwargs)\n              ^^^^^^^^^^^^^^^^^^^^^^^^^^^^^^^^^^^^^^^^^^^^^^^\n  File \"C:\\Users\\HP\\AppData\\Local\\Programs\\Python\\Python311\\Lib\\site-packages\\keras_tuner\\src\\engine\\hypermodel.py\", line 149, in fit\n    return model.fit(*args, **kwargs)\n           ^^^^^^^^^^^^^^^^^^^^^^^^^^\n  File \"C:\\Users\\HP\\AppData\\Local\\Programs\\Python\\Python311\\Lib\\site-packages\\keras\\src\\utils\\traceback_utils.py\", line 122, in error_handler\n    raise e.with_traceback(filtered_tb) from None\n  File \"C:\\Users\\HP\\AppData\\Local\\Programs\\Python\\Python311\\Lib\\site-packages\\keras\\src\\layers\\input_spec.py\", line 227, in assert_input_compatibility\n    raise ValueError(\nValueError: Exception encountered when calling Sequential.call().\n\n\u001b[1mInput 0 of layer \"conv1d\" is incompatible with the layer: expected axis -1 of input shape to have value 1, but received input with shape (None, 13, 100)\u001b[0m\n\nArguments received by Sequential.call():\n  \u2022 inputs=tf.Tensor(shape=(None, 13, 100, 1), dtype=float32)\n  \u2022 training=True\n  \u2022 mask=None\n"}